Workbook

Sheet sheet1
A1: 订单号 | B1: 订单状态 | C1: 负责人（业务员） | D1: 买家名称 | E1: 下单时间 | F1: 付款时间 | G1: 订单金额 | H1: 商品编码 | I1: 完整收货地址 | J1: 收件人名称 | K1: 联系电话 | L1: 手机 | M1: 联系邮件 | N1: 详细地址 | O1: 邮编 | P1: 扩展城市（德/意/波/墨为真实的城市） | Q1: 城市 | R1: 州/省 | S1: 收货国家 | T1: 买家选择物流 | U1: 实际发货单号 | V1: 确认收货时间 | W1: 售后单
A2: 8207841133554507 | B2: 等待发货 | C2: default firstName default lastName | D2: Juan Valiente | E2: 01/16/2026 15:57 | F2: 01/16/2026 15:57 | G2: CN￥ 954.91 | H2: JKM-Y10-PRO * 1 | I2: 8400 NW 25th ST、Miami、Florida、United States | J2: juanpedrobm273605 | K2: +1 | L2: 8092584174 | M2: jprv@yahoo.com | N2: 8400 NW 25th ST | O2: 33122 | Q2: Miami | R2: Florida | S2: United States | T2: AE_US_SAVER | W2: =VLOOKUP(A2,[1]速卖通售后单!$A:$C,2,FALSE) -> #N/A
A3: 3067837993265173 | B3: 等待发货 | C3: default firstName default lastName | D3: Filippo Rosace | E3: 01/16/2026 15:16 | F3: 01/16/2026 15:20 | G3: CN￥ 213.71 | H3: GJ-JLLSD-055+RS1 * 1 | I3: Via Rogoredo 21\D C/O BarTabacchi、20138、Milano、Milano、Lombardia、Italy | J3: Gaia Magenis | K3: 39 | L3: 3490742334 | M3: filo984@hotmail.com | N3: Via Rogoredo 21\D C/O BarTabacchi | O3: 20138 | P3: Milano | Q3: Milano | R3: Lombardia | S3: Italy | T3: SELLER_SHIPPING_DE | W3: =VLOOKUP(A3,[1]速卖通售后单!$A:$C,2,FALSE) -> #N/A
A4: 8208947199356513 | B4: 等待发货 | C4: default firstName default lastName | D4: The Taser Gamer 01 user | E4: 01/16/2026 14:06 | F4: 01/16/2026 14:06 | G4: CN￥ 242.35 | H4: XLW-ele138-BK * 1 | I4: 7321 E 48th st 70-4、Tulsa、Oklahoma、United States | J4: Derrick Mayhue | K4: +1 | L4: 9188591400 | M4: coolguyyy8@gmail.com | N4: 7321 E 48th st 70-4 | O4: 74145 | Q4: Tulsa | R4: Oklahoma | S4: United States | T4: Seller Shpping | W4: =VLOOKUP(A4,[1]速卖通售后单!$A:$C,2,FALSE) -> #N/A
A5: 8208729252504396 | B5: 等待发货 | C5: default firstName default lastName | D5: US20251207ryPq user | E5: 01/16/2026 10:58 | F5: 01/16/2026 10:58 | G5: CN￥ 267.30 | H5: JKM@-ele180in1-BK * 1 | I5: 585 Yellow Jacket Road、Dayton、Nevada、United States | J5: Bruce Davis | K5: +1 | L5: 7755305675 | M5: us20251207rypq_28439@aliexpress.com | N5: 585 Yellow Jacket Road | O5: 89403 | Q5: Dayton | R5: Nevada | S5: United States | T5: AE_US_SAVER | W5: =VLOOKUP(A5,[1]速卖通售后单!$A:$C,2,FALSE) -> #N/A
A6: 3067803675386565 | B6: 等待发货 | C6: default firstName default lastName | D6: Wiśniewski Miłosz | E6: 01/16/2026 02:08 | F6: 01/16/2026 02:08 | G6: CN￥ 185.34 | H6: GJ-JLLSD-055+RS1 * 1 | I6: Sierakowskiego 49、87600、Lipno、Lipno、Kujawsko-Pomorskie、Poland | J6: Milosz Wisniewski | K6: +48 | L6: 606635682 | M6: rrdyzswcfx@privaterelay.appleid.com | N6: Sierakowskiego 49 | O6: 87600 | P6: Lipno | Q6: Lipno | R6: Kujawsko-Pomorskie | S6: Poland | T6: SELLER_SHIPPING_DE | W6: =VLOOKUP(A6,[1]速卖通售后单!$A:$C,2,FALSE) -> #N/A
A7: 3067432197955494 | B7: 等待买家收货 | C7: default firstName default lastName | D7: Yavor Raychev | E7: 01/15/2026 20:24 | F7: 01/15/2026 20:24 | G7: CN￥ 267.30 | H7: JKM@-ele180in1-BK * 1 | I7: 10850 NW 21st ST STE 200、Miami、Florida、United States | J7: Yavor Raychev PANAVANA | K7: +1 | L7: 3058508036 | M7: google_100238807703275667743@aliexpress.com | N7: 10850 NW 21st ST STE 200 | O7: 33172 | Q7: Miami | R7: Florida | S7: United States | T7: AE_US_SAVER | U7: AE_US_SAVER:UUS61G5650882228665 | W7: =VLOOKUP(A7,[1]速卖通售后单!$A:$C,2,FALSE) -> #N/A
A8: 3067515495155308 | B8: 等待买家收货 | C8: default firstName default lastName | D8: Jakub Gorzkiewicz | E8: 01/15/2026 17:51 | F8: 01/15/2026 17:51 | G8: CN￥ 342.58 | H8: JKM@-ELE180in1-Bk-D * 1 | I8: Władysława Króla 47 20、94039、Lodz、Lodzkie、Poland | J8: Jakub Gorzkiewicz | K8: +48 | L8: 798277255 | M8: japper@tlen.pl | N8: Władysława Króla 47 20 | O8: 94039 | Q8: Lodz | R8: Lodzkie | S8: Poland | T8: SELLER_SHIPPING_DE | U8: Seller Shpping DE :887960212963 | W8: =VLOOKUP(A8,[1]速卖通售后单!$A:$C,2,FALSE) -> #N/A
A9: 8207857760625849 | B9: 等待买家收货 | C9: default firstName default lastName | D9: Seovannys Jimenez | E9: 01/15/2026 16:15 | F9: 01/15/2026 16:15 | G9: CN￥ 241.76 | H9: JKM@-180in1-BK * 1 | I9: 8316 NW 68th ST Apt PC-10836、Miami、Florida、United States | J9: Seovannys Jimenez | K9: +1 | L9: 7863594823 | M9: seovannys.j.r@gmail.com | N9: 8316 NW 68th ST Apt PC-10836 | O9: 331662920 | Q9: Miami | R9: Florida | S9: United States | T9: AE_US_SAVER | U9: AE_US_SAVER:UUS61G5650881185519 | W9: =VLOOKUP(A9,[1]速卖通售后单!$A:$C,2,FALSE) -> #N/A
A10: 8208560225255823 | B10: 等待买家收货 | C10: default firstName default lastName | D10: Lorenzo Kevin | E10: 01/15/2026 10:29 | F10: 01/15/2026 10:32 | G10: CN￥ 267.30 | H10: JKM@-ele180in1-BK * 1 | I10: 13435 SW 290th ST、Homestead、Florida、United States | J10: Kevin Lorenzo Valdes | K10: +1 | L10: 7865019153 | M10: kevin547lorenzo@gmail.com | N10: 13435 SW 290th ST | O10: 33033 | Q10: Homestead | R10: Florida | S10: United States | T10: AE_US_SAVER | U10: AE_US_SAVER:UUS61G5650881185497 | W10: =VLOOKUP(A10,[1]速卖通售后单!$A:$C,2,FALSE) -> #N/A
A11: 8208915274070746 | B11: 等待买家收货 | C11: default firstName default lastName | D11: Reginald C | E11: 01/15/2026 10:08 | F11: 01/15/2026 10:08 | G11: CN￥ 267.30 | H11: JKM@-ele180in1-BK * 1 | I11: 250 ashland PL 12E、Brooklyn、New York、United States | J11: Reginald Coupet | K11: +1 | L11: 7188076064 | M11: reggieok2k@gmail.com | N11: 250 ashland PL 12E | O11: 11217 | Q11: Brooklyn | R11: New York | S11: United States | T11: Seller Shpping | U11: Seller Shipping US:GFUS01030164078403 | W11: =VLOOKUP(A11,[1]速卖通售后单!$A:$C,2,FALSE) -> #N/A
A12: 8207846565476069 | B12: 等待买家收货 | C12: default firstName default lastName | D12: trent t | E12: 01/15/2026 08:14 | F12: 01/15/2026 08:14 | G12: CN￥ 235.69 | H12: JKM@-180in1-Wh * 1 | I12: 571 Oceanside Blvd、Indialantic、Florida、United States | J12: Trent Carter | K12: +1 | L12: 3215364944 | M12: trent@trentcarter.com | N12: 571 Oceanside Blvd | O12: 32903 | Q12: Indialantic | R12: Florida | S12: United States | T12: AE_US_SAVER | U12: AE_US_SAVER:CNGF001FL6069000005942579 | W12: =VLOOKUP(A12,[1]速卖通售后单!$A:$C,2,FALSE) -> #N/A
A13: 8207845128809746 | B13: 等待发货 | C13: default firstName default lastName | D13: Juan Lozano | E13: 01/15/2026 07:19 | F13: 01/15/2026 07:19 | G13: CN￥ 152.02 | H13: MT-S1-Sliver * 1 | I13: 40 67 Hampton Street 3B、Elmhurst、New York、United States | J13: Juan M Lozano | K13: +1 | L13: 7184965958 | M13: lozanocjm.jl@gmail.com | N13: 40 67 Hampton Street 3B | O13: 11373 | Q13: Elmhurst | R13: New York | S13: United States | T13: USPS | W13: =VLOOKUP(A13,[1]速卖通售后单!$A:$C,2,FALSE) -> #N/A
A14: 8208695659680800 | B14: 等待发货 | C14: default firstName default lastName | D14: Przemyslaw Leja | E14: 01/15/2026 06:55 | F14: 01/15/2026 06:55 | G14: CN￥ 241.76 | H14: JKM@-180in1-BK * 1 | I14: 280 E houston ST THE HOUSTON LOBBY、New york、New York、United States | J14: DAVID DOORMAN | K14: +1 | L14: 9294226669 | M14: shayd93@gmail.com | N14: 280 E houston ST THE HOUSTON LOBBY | O14: 10002 | Q14: New york | R14: New York | S14: United States | T14: Seller Shpping | W14: =VLOOKUP(A14,[1]速卖通售后单!$A:$C,2,FALSE) -> #N/A
A15: 8208554949570800 | B15: 订单关闭 | C15: default firstName default lastName | D15: P**a | E15: 01/15/2026 06:34 | F15: 01/15/2026 06:34 | G15: CN￥ 235.69 | H15: JKM@-180in1-Wh * 1 | I15: ********uston ST THE HOUSTON LOBBY、New york、New York、United States | J15: DAVI********* | K15: +1 | L15: 92****6669 | M15: shay***@gmail.com | N15: **************************ON LOBBY | O15: 10002 | Q15: New york | R15: New York | S15: United States | T15: Seller Shpping | W15: =VLOOKUP(A15,[1]速卖通售后单!$A:$C,2,FALSE) -> #N/A
A16: 8208051399730819 | B16: 等待买家收货 | C16: default firstName default lastName | D16: Rivera Márquez Alejandro | E16: 01/15/2026 05:43 | F16: 01/15/2026 05:43 | G16: CN￥ 267.30 | H16: JKM@-ele180in1-BK * 1 | I16: 19010 NW 57th AVE Apt 105、Hialeah、Florida、United States | J16: Alejandro Rivera | K16: +1 | L16: 3058483876 | M16: 8jgg2jkm5r@privaterelay.appleid.com | N16: 19010 NW 57th AVE Apt 105 | O16: 33015 | Q16: Hialeah | R16: Florida | S16: United States | T16: AE_US_SAVER | U16: AE_US_SAVER:UUS61G5650881185483 | W16: =VLOOKUP(A16,[1]速卖通售后单!$A:$C,2,FALSE) -> #N/A
A17: 3067275143722078 | B17: 等待买家收货 | C17: default firstName default lastName | D17: wolfgangmw user | E17: 01/15/2026 03:02 | F17: 01/15/2026 03:02 | G17: CN￥ 201.59 | H17: MT-Ele68in-1 * 1 | I17: Am Nußbaum 20、35606、Solms、Lahn-Dill-Kreis、Hessen、Germany | J17: Wolfgang Menk | K17: +49 | L17: 15141266765 | M17: wolfgangmw@gmail.com | N17: Am Nußbaum 20 | O17: 35606 | P17: Solms | Q17: Lahn-Dill-Kreis | R17: Hessen | S17: Germany | T17: SELLER_SHIPPING_DE | U17: Seller Shpping DE :00340434798210050464 | W17: =VLOOKUP(A17,[1]速卖通售后单!$A:$C,2,FALSE) -> #N/A
A18: 3067472376709787 | B18: 等待买家收货 | C18: default firstName default lastName | D18: Bjoern Gloeckner | E18: 01/15/2026 01:43 | F18: 01/15/2026 01:43 | G18: CN￥ 320.81 | H18: JKM@-ELE180in1-Bk-D * 1 | I18: Poissystr. 11-13、66955、Pirmasens、Pirmasens、Rheinland-Pfalz、Germany | J18: Bjoern Gloeckner | K18: +49 | L18: 15201943629 | M18: online-order@cgon.de | N18: Poissystr. 11-13 | O18: 66955 | P18: Pirmasens | Q18: Pirmasens | R18: Rheinland-Pfalz | S18: Germany | T18: SELLER_SHIPPING_DE | U18: Seller Shpping DE :00340434798210050457 | W18: =VLOOKUP(A18,[1]速卖通售后单!$A:$C,2,FALSE) -> #N/A
A19: 8207897788125433 | B19: 等待买家收货 | C19: default firstName default lastName | D19: MX m | E19: 01/15/2026 01:14 | F19: 01/15/2026 01:14 | G19: CN￥ 267.30 | H19: JKM@-ele180in1-BK * 1 | I19: 37 le vista ln、Asheville、North Carolina、United States | J19: Miguel espino | K19: 1 | L19: 8282756716 | M19: miguelespino140@gmail.com | N19: 37 le vista ln | O19: 28806 | Q19: Asheville | R19: North Carolina | S19: United States | T19: Seller Shpping | U19: Seller Shipping US:GFUS01030164067072 | W19: =VLOOKUP(A19,[1]速卖通售后单!$A:$C,2,FALSE) -> #N/A
A20: 3067270585378930 | B20: 等待买家收货 | C20: default firstName default lastName | D20: Isaias Rodriguez Arnesto | E20: 01/15/2026 00:49 | F20: 01/15/2026 00:50 | G20: CN￥ 364.71 | H20: JKM@-ELE180in1-Bk-D * 1 | I20: CALLE ALCAZARQUIVIR N4 BAJO B、Sevilla、Sevilla、Spain | J20: Isaias Rodriguez Arnesto | K20: +34 | L20: 691497987 | M20: isaiasprivado@gmail.com | N20: CALLE ALCAZARQUIVIR N4 BAJO B | O20: 41015 | Q20: Sevilla | R20: Sevilla | S20: Spain | T20: SELLER_SHIPPING_DE | U20: Seller Shpping DE :887960212941 | W20: =VLOOKUP(A20,[1]速卖通售后单!$A:$C,2,FALSE) -> #N/A
A21: 8208444844585486 | B21: 等待买家收货 | C21: default firstName default lastName | D21: Wilson David | E21: 01/14/2026 20:12 | F21: 01/14/2026 20:12 | G21: CN￥ 235.04 | H21: JKM@-180in1-BK * 1 | I21: 8822 Silver Maple Drive、Ooltewah、Tennessee、United States | J21: David Wilson | K21: +1 | L21: 4237186438 | M21: fjmmpcznvw@privaterelay.appleid.com | N21: 8822 Silver Maple Drive | O21: 37363 | Q21: Ooltewah | R21: Tennessee | S21: United States | T21: AE_US_SAVER | U21: AE_US_SAVER:CNGF001FL5486000005996179 | W21: =VLOOKUP(A21,[1]速卖通售后单!$A:$C,2,FALSE) -> #N/A
A22: 8208443243441544 | B22: 等待买家收货 | C22: default firstName default lastName | D22: Stuart Vealey | E22: 01/14/2026 18:43 | F22: 01/14/2026 18:44 | G22: CN￥ 235.86 | H22: XGGJ23110201-180in1 * 1 | I22: 1438 battle creek RD、Charlotte、Michigan、United States | J22: Stuart Vealey | K22: +1 | L22: 5173032468 | M22: stuartvealey@gmail.com | N22: 1438 battle creek RD | O22: 48813 | Q22: Charlotte | R22: Michigan | S22: United States | T22: Seller Shpping | U22: Seller Shipping US:9234690382438000150098 | W22: =VLOOKUP(A22,[1]速卖通售后单!$A:$C,2,FALSE) -> #N/A
A23: 3067450457411762 | B23: 等待买家收货 | C23: default firstName default lastName | D23: DIVERSPORT SL | E23: 01/14/2026 12:34 | F23: 01/14/2026 12:34 | G23: CN￥ 209.31 | H23: GJ-JLLSD-055+RS1 * 1 | I23: AVDA SALVADOR DALI 29 1º1ª、Figueres、Girona、Spain | J23: DIVERSPORT SL B17711474 | K23: +34 | L23: 637304576 | M23: jrdrc51@gmail.com | N23: AVDA SALVADOR DALI 29 1º1ª | O23: 17600 | Q23: Figueres | R23: Girona | S23: Spain | T23: SELLER_SHIPPING_DE | U23: Seller Shpping DE :1Z11H4020420189831 | W23: =VLOOKUP(A23,[1]速卖通售后单!$A:$C,2,FALSE) -> #N/A
A24: 8208428127770939 | B24: 等待买家收货 | C24: default firstName default lastName | D24: pylan76 user | E24: 01/14/2026 08:18 | F24: 01/14/2026 08:18 | G24: CN￥ 242.35 | H24: XLW-ele138-BK * 1 | I24: 404 bent creek TRCE、Chelsea、Alabama、United States | J24: Dylan Williamson | K24: +1 | L24: 2056133310 | M24: pylan76@gmail.com | N24: 404 bent creek TRCE | O24: 35043 | Q24: Chelsea | R24: Alabama | S24: United States | T24: Seller Shpping | U24: Seller Shipping US:9234690382438000150081 | W24: =VLOOKUP(A24,[1]速卖通售后单!$A:$C,2,FALSE) -> #N/A
A25: 8207776654539314 | B25: 等待买家收货 | C25: default firstName default lastName | D25: chadhall71 user | E25: 01/14/2026 04:28 | F25: 01/14/2026 04:28 | G25: CN￥ 267.30 | H25: JKM@-ele180in1-BK * 1 | I25: 1035 meghan LN、King、North Carolina、United States | J25: John Hall | K25: +1 | L25: 3369724645 | M25: chadhall71@yahoo.com | N25: 1035 meghan LN | O25: 27021 | Q25: King | R25: North Carolina | S25: United States | T25: AE_US_SAVER | U25: AE_US_SAVER:CNGF001FL9314000005773556 | W25: =VLOOKUP(A25,[1]速卖通售后单!$A:$C,2,FALSE) -> #N/A
A26: 3067416850141821 | B26: 等待买家收货 | C26: default firstName default lastName | D26: jana user | E26: 01/14/2026 00:19 | F26: 01/14/2026 00:19 | G26: CN￥ 270.15 | H26: JKM@-180in1-Wh * 1 | I26: Am Zenterling 24b、91560、Heilsbronn、Ansbach、Bayern、Germany | J26: Jana Sennewald | K26: +49 | L26: 1714589744 | M26: jana@sennewald.run | N26: Am Zenterling 24b | O26: 91560 | P26: Heilsbronn | Q26: Ansbach | R26: Bayern | S26: Germany | T26: SELLER_SHIPPING_DE | U26: Seller Shpping DE :00340434798210049857 | W26: =VLOOKUP(A26,[1]速卖通售后单!$A:$C,2,FALSE) -> #N/A
A27: 8207868509596593 | B27: 等待买家收货 | C27: default firstName default lastName | D27: arshad.tj.ahmady user | E27: 01/13/2026 23:06 | F27: 01/13/2026 23:06 | G27: CN￥ 154.88 | H27: MT-S1-Sliver * 1 | I27: 18 cheechako rd、Buxton、Maine、United States | J27: Arshad Ahmady | K27: +1 | L27: 2072089270 | M27: arshad.tj.ahmady@gmail.com | N27: 18 cheechako rd | O27: 04093 | Q27: Buxton | R27: Maine | S27: United States | T27: AE_US_SAVER | U27: AE_US_SAVER:CNGF001FL6593000005852599 | W27: =VLOOKUP(A27,[1]速卖通售后单!$A:$C,2,FALSE) -> #N/A
A28: 8207769932313986 | B28: 等待买家收货 | C28: default firstName default lastName | D28: Leandro Alias | E28: 01/13/2026 20:07 | F28: 01/13/2026 20:07 | G28: CN￥ 235.69 | H28: JKM@-180in1-Wh * 1 | I28: 7815 NW 15th ST HUB logistic corp、Doral、Florida、United States | J28: leandro SOS LOGIC alias | K28: +1 | L28: 3056405422 | M28: aliasleandro@gmail.com | N28: 7815 NW 15th ST HUB logistic corp | O28: 33126 | Q28: Doral | R28: Florida | S28: United States | T28: AE_US_SAVER | U28: AE_US_SAVER:UUS61E5650868675098 | W28: =VLOOKUP(A28,[1]速卖通售后单!$A:$C,2,FALSE) -> #N/A
A29: 8207809447939581 | B29: 等待买家收货 | C29: default firstName default lastName | D29: Edgar Martinez | E29: 01/13/2026 19:42 | F29: 01/13/2026 19:42 | G29: CN￥ 235.69 | H29: JKM@-180in1-Wh * 1 | I29: 235 spring ST 2a、Ossining、New York、United States | J29: Edgar Martinez | K29: +1 | L29: 9142529142 | M29: roamingrepairs.llc@gmail.com | N29: 235 spring ST 2a | O29: 10562 | Q29: Ossining | R29: New York | S29: United States | T29: AE_US_SAVER | U29: AE_US_SAVER:UUS61E5650868675066 | W29: =VLOOKUP(A29,[1]速卖通售后单!$A:$C,2,FALSE) -> #N/A
A30: 8207862345420665 | B30: 等待买家收货 | C30: default firstName default lastName | D30: kiandeguzman18 user | E30: 01/13/2026 18:26 | F30: 01/13/2026 18:26 | G30: CN￥ 220.32 | H30: LX-RS66IN1 * 1 | I30: 36 Bog and Vly Ln、Lincoln park、New Jersey、United States | J30: Kristian Deguzman | K30: +1 | L30: 8622210699 | M30: kiandeguzman18@yahoo.com | N30: 36 Bog and Vly Ln | O30: 07035 | Q30: Lincoln park | R30: New Jersey | S30: United States | T30: AE_US_SAVER | U30: AE_US_SAVER:UUS61E5650868675078 | W30: =VLOOKUP(A30,[1]速卖通售后单!$A:$C,2,FALSE) -> #N/A
A31: 8207764016206690 | B31: 等待买家收货 | C31: default firstName default lastName | D31: DP White | E31: 01/13/2026 16:45 | F31: 01/13/2026 16:45 | G31: CN￥ 267.30 | H31: JKM@-ele180in1-BK * 1 | I31: 6404 Hwy 98 East, Comer, GA 30629、Madison County、Georgia、United States | J31: David Parks White | K31: +1 | L31: 7069556424 | M31: davidparkswhite@gmail.com | N31: 6404 Hwy 98 East, Comer, GA 30629 | O31: 30629 | Q31: Madison County | R31: Georgia | S31: United States | T31: AE_US_SAVER | U31: AE_US_SAVER:CNGF001FL6690000005769306 | W31: =VLOOKUP(A31,[1]速卖通售后单!$A:$C,2,FALSE) -> #N/A
A32: 8208011557663958 | B32: 等待买家收货 | C32: default firstName default lastName | D32: jon user | E32: 01/13/2026 15:37 | F32: 01/13/2026 15:37 | G32: CN￥ 241.76 | H32: JKM@-180in1-BK * 1 | I32: 49 crest AVE、Revere、Massachusetts、United States | J32: Jon Sargent | K32: +1 | L32: 8029893027 | M32: jon@kannedheatkitchen.com | N32: 49 crest AVE | O32: 02151 | Q32: Revere | R32: Massachusetts | S32: United States | T32: AE_US_SAVER | U32: AE_US_SAVER:UUS61E5650866917823 | W32: =VLOOKUP(A32,[1]速卖通售后单!$A:$C,2,FALSE) -> #N/A
A33: 3066983360464850 | B33: 交易完成 | C33: default firstName default lastName | D33: Alexey Karyazin | E33: 01/13/2026 13:39 | F33: 01/13/2026 13:39 | G33: CN￥ 258.31 | H33: AS-RS2-BK * 1 | I33: rauterbergweg 3b、29221、Celle、Niedersachsen、Germany | J33: alexey karyazin | K33: +49 | L33: 17647336233 | M33: alexeyka@kabelmail.de | N33: rauterbergweg 3b | O33: 29221 | Q33: Celle | R33: Niedersachsen | S33: Germany | T33: SELLER_SHIPPING_DE | U33: Seller Shpping DE :00340434798210049659 | V33: 01/16/2026 09:37 | W33: =VLOOKUP(A33,[1]速卖通售后单!$A:$C,2,FALSE) -> #N/A
A34: 8208505421632938 | B34: 等待买家收货 | C34: default firstName default lastName | D34: Michael Pierno | E34: 01/13/2026 13:33 | F34: 01/13/2026 13:33 | G34: CN￥ 241.76 | H34: JKM@-180in1-BK * 1 | I34: 457 Park Rd、Dingmans ferry、Pennsylvania、United States | J34: Michael Pierno | K34: +1 | L34: 8453210237 | M34: arsenic@aol.com | N34: 457 Park Rd | O34: 18328 | Q34: Dingmans ferry | R34: Pennsylvania | S34: United States | T34: Seller Shpping | U34: Seller Shipping US:9234690382438000150050 | W34: =VLOOKUP(A34,[1]速卖通售后单!$A:$C,2,FALSE) -> #N/A
A35: 3067121851402114 | B35: 等待买家收货 | C35: default firstName default lastName | D35: Michael Da Silva Abreu | E35: 01/13/2026 12:52 | F35: 01/13/2026 12:52 | G35: CN￥ 240.18 | H35: LX-RS66IN1 * 1 | I35: Waldstraße 8、65462、Ginsheim-Gustavsburg、Gross-Gerau、Hessen、Germany | J35: Michael Da Silva Abreu | K35: +49 | L35: 16097691928 | M35: michael.da.silva.abreu@gmail.com | N35: Waldstraße 8 | O35: 65462 | P35: Ginsheim-Gustavsburg | Q35: Gross-Gerau | R35: Hessen | S35: Germany | T35: SELLER_SHIPPING_DE | U35: Seller Shpping DE :00340434798210049642 | W35: =VLOOKUP(A35,[1]速卖通售后单!$A:$C,2,FALSE) -> #N/A
A36: 3067303005021259 | B36: 等待买家收货 | C36: default firstName default lastName | D36: Edu Corominas | E36: 01/13/2026 12:37 | F36: 01/13/2026 12:37 | G36: CN￥ 309.89 | H36: JKM@-180in1-Wh * 1 | I36: 12 Carrer Tenor Viñas 2 piso 2 puerta、Teia、Barcelona、Spain | J36: Eduard Corominas | K36: +34 | L36: 649856314 | M36: eduardcoro@hotmail.com | N36: 12 Carrer Tenor Viñas 2 piso 2 puerta | O36: 08329 | Q36: Teia | R36: Barcelona | S36: Spain | T36: SELLER_SHIPPING_DE | U36: Seller Shpping DE :887890821471 | W36: =VLOOKUP(A36,[1]速卖通售后单!$A:$C,2,FALSE) -> #N/A
A37: 8208003639459399 | B37: 等待买家收货 | C37: default firstName default lastName | D37: Tiffany user | E37: 01/13/2026 09:52 | F37: 01/13/2026 09:52 | G37: CN￥ 274.73 | H37: JKM@-ele180in1-BK * 1 | I37: 1637 county road 307、Poplar bluff、Missouri、United States | J37: Tiffany Chestnut | K37: +1 | L37: 5737723056 | M37: facebook_1009197560917282@aliexpress.com | N37: 1637 county road 307 | O37: 63901 | Q37: Poplar bluff | R37: Missouri | S37: United States | T37: AE_US_SAVER | U37: AE_US_SAVER:CNGF001FL9399000005535228 | W37: =VLOOKUP(A37,[1]速卖通售后单!$A:$C,2,FALSE) -> #N/A
A38: 8208855039512330 | B38: 等待买家收货 | C38: default firstName default lastName | D38: Harrsion Feng | E38: 01/13/2026 08:47 | F38: 01/13/2026 08:47 | G38: CN￥ 274.73 | H38: JKM@-ele180in1-BK * 1 | I38: 8626 108TH ST、Jamaica、New York、United States | J38: Jingquan Feng | K38: 1 | L38: 9172546731 | M38: google_103501381809389016114@aliexpress.com | N38: 8626 108TH ST | O38: 11418 | Q38: Jamaica | R38: New York | S38: United States | T38: AE_US_SAVER | U38: AE_US_SAVER:UUS61E5650866917812 | W38: =VLOOKUP(A38,[1]速卖通售后单!$A:$C,2,FALSE) -> #N/A
A39: 8208393325141995 | B39: 等待买家收货 | C39: default firstName default lastName | D39: jazlynbr1 user | E39: 01/12/2026 22:07 | F39: 01/12/2026 22:07 | G39: CN￥ 267.30 | H39: JKM@-ele180in1-BK * 1 | I39: 960 grand concourse APT 3H、Bronx、New York、United States | J39: Adrian Pero | K39: +1 | L39: 9296310407 | M39: jazlynbr1@hotmail.com | N39: 960 grand concourse APT 3H | O39: 10451 | Q39: Bronx | R39: New York | S39: United States | T39: AE_US_SAVER | U39: AE_US_SAVER:CNGF001FL1995000005593825 | W39: =VLOOKUP(A39,[1]速卖通售后单!$A:$C,2,FALSE) -> #N/A
A40: 8208842077785806 | B40: 等待买家收货 | C40: default firstName default lastName | D40: The Wildcard | E40: 01/12/2026 18:48 | F40: 01/12/2026 18:48 | G40: CN￥ 152.02 | H40: MT-S1-Sliver * 1 | I40: 5540 NW 31st AVE APT 309、Fort lauderdale、Florida、United States | J40: Albert Waldo | K40: +1 | L40: 9547404891 | M40: aawaldo1989@gmail.com | N40: 5540 NW 31st AVE APT 309 | O40: 33309 | Q40: Fort lauderdale | R40: Florida | S40: United States | T40: AE_US_SAVER | U40: AE_US_SAVER:UUS61D5650863379778 | W40: =VLOOKUP(A40,[1]速卖通售后单!$A:$C,2,FALSE) -> #N/A
...
